<?xml version="1.0"?>
<robot name="pan_tilt">
<!-- *********************************** BASE LINK ***************************    -->
  <link name="base_link">
  <visual>
      <geometry>
	     <cylinder length="0.2" radius="0.3"/>
      </geometry>
      <origin rpy="0 0 0" xyz="0 0 0"/>
      <material name="yellow">
             <color rgba="1 1 0 0.5"/> 
      </material>
    </visual>
 </link>

<!-- *********************************** PAN LINK ***************************    -->
  <joint name="pan_joint" type="revolute">
    <parent link="base_link"/>
    <child link="pan_link"/>
    <origin rpy="0 0 0" xyz="0 0 0.1"/> <!-- 0.1 m en z desde base link-->
    <axis xyz="0 0 1" />		<!-- rotacion sobre el eje z-->
    <limit effort="300" velocity="0.1" lower="-3.14" upper="3.14"/>
  </joint>

  <link name="pan_link">
    <visual>
      <geometry>
	<cylinder length="0.6" radius="0.04"/>
      </geometry>
      <origin rpy="0 0 0" xyz="0 0 0.3"/>
      <material name="red">
        <color rgba="0 0 1 1"/>
      </material>
    </visual>

    <collision>
      <geometry>
	<cylinder length="0.4" radius="0.1"/>
      </geometry>
      <origin rpy="0 0 0" xyz="0 0 0.3"/>
    </collision>
    <inertial>
	<mass value="1"/>
	<inertia ixx="1.0" ixy="0.0" ixz="0.0" iyy="1.0" iyz="0.0" izz="1.0"/>
    </inertial>
  </link>


<!-- *********************************** TILT LINK ***************************    -->
  <joint name="tilt_joint" type="revolute">
    <parent link="pan_link"/>
    <child link="tilt_link"/>
    <origin rpy="0 0 0" xyz="0 0 0.63"/>
    <axis xyz="	1 0 0" />
    <limit effort="300" velocity="0.1" lower="-4.64" upper="-1.5"/>
  </joint>



  <link name="tilt_link">
    <visual>
      <geometry>
	<cylinder length="0.4" radius="0.06"/>
      </geometry>
      <origin rpy="1.57075 0 0" xyz="0 0 0"/> <!-- rotacion del cilindro 90ยบ sobre el ejex -->
      <material name="green">
        <color rgba="1 0 0 1"/>
      </material>
    </visual>

    <collision>
      <geometry>
	<cylinder length="0.4" radius="0.06"/>
      </geometry>
      <origin rpy="1.57075 0 0" xyz="0 0 0"/>
    </collision>
    <inertial>
	<mass value="1"/>
	<inertia ixx="1.0" ixy="0.0" ixz="0.0" iyy="1.0" iyz="0.0" izz="1.0"/>
    </inertial>

  </link>


</robot>
